Workbook

Sheet Leggimi
A1: Libreria analisi dei rischi – prima estrazione
A3: Origine: Valutazione dei rischi 200741V rev. 0.0 del 22.05.2020, Impianto di smerigliatura e lucidatura rubinetteria mod. 3 IR 50/6 USNR + TR 5/4 CNC (versioni PDF "aggiornata" di relazione introduttiva e schede RESS).
A4: I testi sono estratti in automatico dal PDF: prima di riusarli vanno riletti. Immagini e figure non sono riportate.
A6: Fogli
A7: Libreria – una riga per ogni scheda di valutazione (78), con zona, modulo, pericoli, stime, misure, testo per le istruzioni e norme.
A8: Moduli – i moduli ricavati dalle schede, con il conteggio delle righe.
A9: RESS-Regolamento – tutti i requisiti della parte 1 dell'Allegato I della Direttiva, se sono trattati nel documento e a quale punto dell'Allegato III del Regolamento (UE) 2023/1230 corrispondono.
A10: Norme – le norme citate nella relazione e le edizioni più recenti a me note.
A11: Punti aperti – le decisioni da prendere prima di usare la libreria per le nuove commesse.
A12: Metodo – matrice e scale del metodo di stima, usate dalle formule.
A14: Come si usa
A15: Celle gialle: sono quelle da compilare o rivedere (condizione di attivazione, note di revisione, decisioni).
... A18: La colonna "Novità del Regolamento" è una sintesi: prima di usarla in un fascicolo va confrontata con il testo ufficiale del Regolamento.

Sheet Libreria
A1: ID | B1: RESS 2006/42/CE | C1: Titolo requisito | D1: Scheda originale | E1: Zona impianto | F1: Modulo | G1: Condizione di attivazione (da rivedere) | H1: Zona pericolosa | I1: Condizioni operative | J1: Pericoli | K1: Se iniz. | L1: Fr iniz. | M1: Pr iniz. | N1: Av iniz. | O1: Cl iniz. | P1: Esito iniziale | Q1: Misure di protezione | R1: Indicazioni per le istruzioni / rischio residuo | S1: Se fin. | T1: Fr fin. | U1: Pr fin. | V1: Av fin. | W1: Cl fin. | X1: Esito finale | Y1: Norme citate | Z1: Note di revisione
A2: LIB-001 | B2: 1.1.1 | C2: Definizioni | D2: VRQ-001 | E2: Impianto | F2: Generale impianto | G2: Sempre | I2: Tutte. | O2: =IF(COUNT(L2:N2)=3,SUM(L2:N2),"") | P2: =IF(OR(K2="",O2=""),"",INDEX(Metodo!$C$6:$G$9,MATCH(K2,Metodo!$B$6:$B$9,0),MATCH(O2,Metodo!$C$5:$G$5,1))) | Q2: Informazioni nelle istruzioni | R2: Nel manuale saranno riportate e chiarite le definizioni del presente RESS. | W2: =IF(COUNT(T2:V2)=3,SUM(T2:V2),"") | X2: =IF(OR(S2="",W2=""),"",INDEX(Metodo!$C$6:$G$9,MATCH(S2,Metodo!$B$6:$B$9,0),MATCH(W2,Metodo!$C$5:$G$5,1))) | Y2: Norme A: EN ISO 12100 | Norme: ISO/TR 14121-2 | Z2: Scheda descrittiva, senza stima del rischio.
A3: LIB-002 | B3: 1.1.2 | C3: Principi d'integrazione della sicurezza | D3: VRQ-001 | E3: Impianto | F3: Generale impianto | G3: Sempre | I3: Tutte. | O3: =IF(COUNT(L3:N3)=3,SUM(L3:N3),"") | P3: =IF(OR(K3="",O3=""),"",INDEX(Metodo!$C$6:$G$9,MATCH(K3,Metodo!$B$6:$B$9,0),MATCH(O3,Metodo!$C$5:$G$5,1))) | Q3: L’Impianto di smerigliatura e lucidatura rubinetteria viene progettato per eseguire in modo automatico le operazioni di smerigliatura e, successivamente, di pulitura di componenti di rubinetteria. L'impianto sarà realizzato con due zone di lavoro, di smerigliatura e di pulitura, ognuna con una propria cabina di protezione e fonti di alimentazione. La zona di smerigliatura sarà costituita dai seguenti elementi: - Stazione di carico a doppio pallet; - nr. 3 gruppi di smerigliatura, costituita da un robot antropomorfo e due smerigliatrici a nastro; - nr. 2 dispositivi per il passaggio del pezzo da un gruppo di smerigliatura a un altro; - Trasportatore a tappeto di scarico. La zona di pulitura sarà costituita dai seguenti elementi: - Tavola rotante con 5 gruppi porta-pezzi; - nr. 4 unità di lucidatura CNC; - Impianto della pasta abrasiva a servizio delle stazioni di lucidatura. Le fonti di alimentazione di energia dell'impianto saranno elettrica e pneumatica. L'impianto viene progettato cercando di eliminare ogni possibile rischio. In linea generale verranno seguite le norme EN ISO 10218-2:2011 e 11161:2010. A tal proposito sarà dotato di: - Ripari fissi perimetrali: cabina di protezione con pannelli fonoassorbenti e finestre per la visione della zona interna; - Ripari mobili interbloccati: porte di accesso alla zona di lavoro, interbloccati con bloccaggio della porta; - Sistemi di comando e controllo; - Manuale d'uso con avvertenze, informazioni sui rischi residui e operazioni di manutenzione. Le uniche operazioni che l'operatore addetto alla conduzione dovrà eseguire, oltre a sovrintendere alle operazioni dell'impianto, saranno quelle di: - Caricare (all'occorrenza) i pezzi da lavorare sui pallet della stazione di carico (in zona classificata di carico) della zona di smerigliatura; - A ogni rotazione della tavola rotante della zona di pulitura, scaricare il pezzo lavorato e caricarne uno da lucidare, prelevandolo dal trasportatore a nastro, in uscita dalla zona di smerigliatura. A seconda del tipo di prodotto che si intende lavorare (fra quelli previsti dall'impianto), sarà necessario compiere delle operazioni di attrezzaggio. In particolare, se necessario, si dovranno sostituire le pinze di presa del pezzo sui gruppi di manipolazione, quali, i robot antropomorfi, la tavola rotante a 5 passi, nonché i due pallet porta-pezzi della stazione di carico. Tutti i rischi residui saranno segnalati e riportati nel manuale di istruzione dell'impianto. Verranno fornite indicazioni in merito ai DPI da utilizzare. | W3: =IF(COUNT(T3:V3)=3,SUM(T3:V3),"") | X3: =IF(OR(S3="",W3=""),"",INDEX(Metodo!$C$6:$G$9,MATCH(S3,Metodo!$B$6:$B$9,0),MATCH(W3,Metodo!$C$5:$G$5,1))) | Y3: Norme A: EN ISO 12100 | Norme: ISO/TR 14121-2 | Z3: Scheda descrittiva, senza stima del rischio.
A4: LIB-003 | B4: 1.1.3 | C4: Materiali e prodotti | D4: VRQ-001 | E4: Impianto | F4: Generale impianto | G4: Sempre | H4: Le parti dell'impianto | I4: Normale. | J4: 6.1 Pericoli generati da materiali e sostanze trattate, utilizzate o scaricate dalla macchina 6.2 Pericoli da contatto o inalazione di fluidi dannosi, gas, nebbie, fumi e polveri che hanno effetto dannoso, tossico, corrosivo e/o irritante 6.4 Pericoli biologici (es. muffe) e microbiologici (virus e batteri) | K4: 2 | L4: 4 | M4: 2 | N4: 3 | O4: =IF(COUNT(L4:N4)=3,SUM(L4:N4),"") -> 9 | P4: =IF(OR(K4="",O4=""),"",INDEX(Metodo!$C$6:$G$9,MATCH(K4,Metodo!$B$6:$B$9,0),MATCH(O4,Metodo!$C$5:$G$5,1))) -> Suggerite | Q4: L’Impianto di smerigliatura e lucidatura rubinetteria viene progettato per eseguire in modo automatico le operazioni di smerigliatura e, successivamente, di pulitura di componenti di rubinetteria. L'impianto sarà realizzato con due zone di lavoro, di smerigliatura e di pulitura, ognuna con una propria cabina di protezione e fonti di alimentazione. La zona di smerigliatura sarà costituita dai seguenti elementi: - Stazione di carico a doppio pallet; - nr. 3 gruppi di smerigliatura, costituita da un robot antropomorfo e due smerigliatrici a nastro; - nr. 2 dispositivi per il passaggio del pezzo da un gruppo di smerigliatura a un altro; - Trasportatore a tappeto di scarico. La zona di pulitura sarà costituita dai seguenti elementi: - Tavola rotante con 5 gruppi porta-pezzi; - nr. 4 unità di lucidatura CNC; - Impianto della pasta abrasiva a servizio delle stazioni di lucidatura. Le fonti di alimentazione di energia dell'impianto saranno elettrica e pneumatica. I materiali scelti ed utilizzati per la costruzione delle varie parti dell’impianto non presenteranno particolari pericoli. Questi saranno materiali inerti che non emetteranno sostanze dannose per gli operatori durante il normale utilizzo dell'impianto: - Acciaio inox e acciaio zincato-verniciato; - Alluminio; - Vetro antisfondamento; - Vari materiali plastici di commercio (maniglie, pomelli, ecc.); - Policarbonato; - Apparecchiature elettriche ed elettroniche; - Cavi elettrici; - Altri materiali minori (viti, dadi, ecc.). Il progetto strutturale dell’intero impianto sarà realizzato da: C.O.S.M.A.P. srl Vedere i "Disegni" e gli "Schemi meccanici" del Fascicolo Tecnico. Il progetto dell’equipaggiamento elettrico sarà realizzato da: C.G.A. Automazioni srl Vedere gli "schemi elettrici" all'interno del Fascicolo Tecnico. Il progetto dell’equipaggiamento pneumatico sarà realizzato da: C.O.S.M.A.P. srl Vedere gli "schemi pneumatici" all'interno del Fascicolo Tecnico. Per quanto riguarda le polveri e sostanze che si formano durante la produzione, vedere quanto indicato al RESS 1.5.13. | R4: Nelle istruzioni dell'impianto saranno indicate le manutenzioni da eseguire per mantenere l'integrità delle parti. | S4: 2 | T4: 2 | U4: 1 | V4: 3 | W4: =IF(COUNT(T4:V4)=3,SUM(T4:V4),"") -> 6 | X4: =IF(OR(S4="",W4=""),"",INDEX(Metodo!$C$6:$G$9,MATCH(S4,Metodo!$B$6:$B$9,0),MATCH(W4,Metodo!$C$5:$G$5,1))) -> OK | Y4: Norme A: EN ISO 12100 | Norme: ISO/TR 14121-2
A5: LIB-004 | B5: 1.1.3 | C5: Materiali e prodotti | D5: VRQ-200 | E5: Pulitura | F5: Impianto pasta abrasiva | G5: Se presente impianto pasta abrasiva | H5: Zona di pulitura con impianto della pasta abrasiva | I5: Normale; manutenzione. | J5: 6.1 Pericoli generati da materiali e sostanze trattate, utilizzate o scaricate dalla macchina 6.2 Pericoli da contatto o inalazione di fluidi dannosi, gas, nebbie, fumi e polveri che hanno effetto dannoso, tossico, corrosivo e/o irritante | K5: 2 | L5: 5 | M5: 2 | N5: 3 | O5: =IF(COUNT(L5:N5)=3,SUM(L5:N5),"") -> 10 | P5: =IF(OR(K5="",O5=""),"",INDEX(Metodo!$C$6:$G$9,MATCH(K5,Metodo!$B$6:$B$9,0),MATCH(O5,Metodo!$C$5:$G$5,1))) -> Suggerite | Q5: L’Impianto di smerigliatura e lucidatura rubinetteria viene progettato per eseguire in modo automatico le operazioni di smerigliatura e successivamente di pulitura di componenti di rubinetteria in lega di ottone. La zona di pulitura dell'impianto sarà dotata di impianto per la pasta abrasiva, necessario per eseguire le operazioni di pulitura. L'impianto della pasta abrasiva sarà realizzato principalmente con componenti di commercio, come i serbatoi con pompa pneumatica di mandata e le pistole spruzzatrici. Saranno presenti: - una pistola spruzzatrice su ciascuna unità di lucidatura CNC; - nr. 2 serbatoi (silos) per contenere due tipologie di pasta abrasiva; - circuiti di alimentazione (singolo o doppio) per tutte le pistole spruzzatrici. Per la tipologia di pasta abrasiva che verrà utilizzata sull’impianto, questa verrà scelta dall’utilizzatore, in base alle specifiche esigenze produttive. Durante il funzionamento dell'impianto, quindi, verrà spruzzata pasta abrasiva sulle spazzole di lucidatura. Anche se la zona di pulitura verrà predisposta con punti di captazione localizzati (sulle cuffie delle unità di lucidatura CNC) da collegare ad un impianto di aspirazione (vedere RESS 1.5.13), il mix di sostanze formate dal materiale lucidato e dalle paste abrasive, potranno depositarsi sulle superfici delle parti dell'impianto e della zona circoscritta (visto l'alto livello di umidità della pasta). La cabina di protezione della zona di pulitura, quindi, permetterà il contenimento delle sostanze, ed eviterà che queste vengano disperse nell'ambiente. A misura di protezione si daranno indicazioni nelle istruzioni di eseguire frequentemente la pulizia della zona di pulitura dell'impianto. Vedere gli "schemi dell'impianto pasta" del Fascicolo Tecnico. | R5: Nelle istruzioni dell'impianto si riporterà di ottemperare alle avvertenze indicate nelle schede tecniche delle paste abrasive in uso. | S5: 2 | T5: 4 | U5: 1 | V5: 1 | W5: =IF(COUNT(T5:V5)=3,SUM(T5:V5),"") -> 6 | X5: =IF(OR(S5="",W5=""),"",INDEX(Metodo!$C$6:$G$9,MATCH(S5,Metodo!$B$6:$B$9,0),MATCH(W5,Metodo!$C$5:$G$5,1))) -> OK | Y5: Norme A: EN ISO 12100 | Norme: ISO/TR 14121-2
A6: LIB-005 | B6: 1.1.4 | C6: Illuminazione | D6: VRQ-001 | E6: Impianto | F6: Generale impianto | G6: Sempre | H6: Tutte le zone dell'impianto | I6: Normale; manutenzione; regolazione / attrezzamento; programmazione; sblocco anomalie. | J6: 9.2.1 Pericoli provocati da inadeguata illuminazione locale | K6: 2 | L6: 5 | M6: 3 | N6: 3 | O6: =IF(COUNT(L6:N6)=3,SUM(L6:N6),"") -> 11 | P6: =IF(OR(K6="",O6=""),"",INDEX(Metodo!$C$6:$G$9,MATCH(K6,Metodo!$B$6:$B$9,0),MATCH(O6,Metodo!$C$5:$G$5,1))) -> Richieste | Q6: L'impianto viene progettato per funzionare in un ambiente industriale coperto. Per quanto riguarda lo spazio intorno all'impianto, dove l'operatore transiterà e stazionerà, verranno date informazioni mediante le istruzioni: l'utilizzatore dovrà garantire un ambiente dove l'impianto verrà installato con una illuminazione sufficiente. Per quanto riguarda lo spazio circoscritto delle cabine di protezione, all'interno della zona di smerigliatura e della zona di pulitura, saranno presenti delle lampade di illuminazione, in grado di illuminare efficacemente tutte le parti della zona. Dove sarà prevista una frequente ispezione e regolazione verrà garantire un'illuminazione di almeno 500 lux. | R6: Sul manuale di istruzioni si riporterà l'obbligo di installare l'impianto in un ambiente sufficientemente illuminato. | S6: 2 | T6: 4 | U6: 1 | V6: 1 | W6: =IF(COUNT(T6:V6)=3,SUM(T6:V6),"") -> 6 | X6: =IF(OR(S6="",W6=""),"",INDEX(Metodo!$C$6:$G$9,MATCH(S6,Metodo!$B$6:$B$9,0),MATCH(W6,Metodo!$C$5:$G$5,1))) -> OK | Y6: Norme A: EN ISO 12100 Norme B: EN 1837 | Norme: ISO/TR 14121-2
A7: LIB-006 | B7: 1.1.5 | C7: Progettazione della macchina ai fini della movimentazione | D7: VRQ-001 | E7: Impianto | F7: Generale impianto | G7: Sempre | H7: Tutte le zone al di sotto e/o in prossimità di un elemento dell'impianto durante le operazioni di movimentazione | I7: Trasporto; Installazione; Smantellamento. | J7: 1.1.1 Pericolo di schiacciamento 1.1.6 Pericolo di urto 1.2.3 Massa e stabilità (energia potenziale di elementi che possono spostarsi sotto l'effetto della gravità) | K7: 3 | L7: 2 | M7: 4 | N7: 5 | O7: =IF(COUNT(L7:N7)=3,SUM(L7:N7),"") -> 11 | P7: =IF(OR(K7="",O7=""),"",INDEX(Metodo!$C$6:$G$9,MATCH(K7,Metodo!$B$6:$B$9,0),MATCH(O7,Metodo!$C$5:$G$5,1))) -> Richieste | Q7: Tutti gli elementi dell'impianto potranno essere sollevati e/o movimentati mediante un dispositivo di sollevamento dall'alto o anche, in alcuni casi, con un carrello elevatore. Vengono date informazioni nelle istruzioni. In ogni caso, l'operazione di trasporto e movimentazione sarà effettuata esclusivamente dal personale preposto e autorizzato. Vedere gli "schemi di sollevamento" alla sezione "Disegni di dettaglio" del fascicolo tecnico. | R7: Le istruzioni dell'impianto riporteranno: - Le masse degli elementi che formano l'impianto; - I disegni per il loro sollevamento; - Indicazioni sul corretto trasporto e movimentazione. | S7: 3 | T7: 2 | U7: 1 | V7: 1 | W7: =IF(COUNT(T7:V7)=3,SUM(T7:V7),"") -> 4 | X7: =IF(OR(S7="",W7=""),"",INDEX(Metodo!$C$6:$G$9,MATCH(S7,Metodo!$B$6:$B$9,0),MATCH(W7,Metodo!$C$5:$G$5,1))) -> OK | Y7: Norme A: EN ISO 12100 Norme B: EN 1005-2; EN 1005-4 | Norme: ISO/TR 14121-2
A8: LIB-007 | B8: 1.1.6 | C8: Ergonomia | D8: VRQ-001 | E8: Impianto | F8: Generale impianto | G8: Sempre | H8: Tutte le postazioni di lavoro per l'operatore | I8: Normale; manutenzione; regolazione / attrezzamento. | J8: 9.1.1 Pericoli provocati da posizioni insalubri 9.1.3 Pericoli provocati da inadeguata progettazione o identificazione dei comandi manuali 9.2.2 Pericoli provocati da eccessivo o scarso impegno mentale, tensione 9.3.1 Pericoli provocati da errore umano, comportamento umano | K8: 2 | L8: 5 | M8: 2 | N8: 3 | O8: =IF(COUNT(L8:N8)=3,SUM(L8:N8),"") -> 10 | P8: =IF(OR(K8="",O8=""),"",INDEX(Metodo!$C$6:$G$9,MATCH(K8,Metodo!$B$6:$B$9,0),MATCH(O8,Metodo!$C$5:$G$5,1))) -> Suggerite | Q8: L’Impianto di smerigliatura e lucidatura rubinetteria viene progettato per eseguire in modo automatico le operazioni di smerigliatura e, successivamente, di pulitura di componenti di rubinetteria. L'impianto sarà realizzato con due zone di lavoro, di smerigliatura e di pulitura, ognuna con una propria cabina di protezione e fonti di alimentazione. Per l'impiego dell'impianto sarà previsto un corridoio di transito di almeno 1000 mm intorno alle cabine di protezione, aumentato a circa 2000 mm in corrispondenza delle postazioni di conduzione per l'operatore (di fronte ai pannelli di controllo, stazioni di carico e di scarico). Una volta eseguite le regolazioni preliminari, la produzione verrà eseguita con ciclo di lavoro in modalità automatica. Durante il normale funzionamento dell'impianto, l'operatore stazionerà all'esterno delle cabine di protezione, di fronte ai quadri elettrici principali o in corrispondenza della zona di carico/scarico dei pezzi. Quando necessario, si porterà in zona di carico per il rifornimento dei pezzi da lavorare nella zona di smerigliatura. I dispositivi di comando verranno posizionati ad un'altezza compresa fra i 600 e i 1700 mm dal pavimento. I pallet porta-pezzi della stazione di carico della zona di smerigliatura, che dovranno essere riempiti manualmente dall'operatore saranno ad un'altezza dal pavimento non inferiore agli 800 mm. Il tappeto del trasportatore di scarico della zona di smerigliatura sarà ad un'altezza dal pavimento di circa 1100 mm. I gruppi porta-pezzo della tavola rotante della zona di pulitura, quando in posizione di riposo (e quindi quella prevista in corrispondenza della posizione di carico/scarico), avranno la pinza porta-pezzo ad un'altezza di circa 1100 mm. Il varco per il carico/scarico dei pezzi sulla tavola rotante, da cui l'operatore dovrà introdurre le mani ed eseguire le operazioni di carico e scarico dei pezzi sarà della dimensione utile per eseguire in modo ergonomico il compito. Da quanto sopra riportato non si rilevano particolari problematiche concernenti l’ergonomia considerando anche che il ritmo di lavoro non è condizionato dalla macchina (ad es. non occorre fermare il ciclo di lavoro automatico per il rifornimento dei pezzi o per lo scarico) e che non è richiesta una concentrazione prolungata nel controllo dell'impianto da parte dell'operatore addetto alla conduzione. Opportune segnalazioni indicheranno lo stato delle due zone di lavoro. Vedere le sezioni Disegni del fascicolo tecnico. | R8: Nelle istruzioni dell'impianto verranno indicate: - Le dimensioni minime dello spazio necessario all'impianto per il suo corretto funzionamento, che devono essere garantite in fase di installazione. | S8: 2 | T8: 3 | U8: 1 | V8: 1 | W8: =IF(COUNT(T8:V8)=3,SUM(T8:V8),"") -> 5 | X8: =IF(OR(S8="",W8=""),"",INDEX(Metodo!$C$6:$G$9,MATCH(S8,Metodo!$B$6:$B$9,0),MATCH(W8,Metodo!$C$5:$G$5,1))) -> OK | Y8: Norme A: EN ISO 12100 Norme B: EN 1005-2; EN 1005-3; EN 1005-4; EN 1005-5; EN 614-1; EN 614-2; EN 547-3; EN 894-1; EN 894-2; EN 894-3; EN 894-4; EN ISO 13732-1; EN ISO 13732-3; EN ISO 7731; EN ISO 14738; EN ISO 15536-1 | Norme: ISO/TR 14121-2
A9: LIB-008 | B9: 1.2.1 | C9: Sicurezza ed affidabilità dei sistemi di comando | D9: VRQ-001 | E9: Impianto | F9: Sistema di comando | G9: Sempre | H9: Tutte le parti mobili e attive dell'impianto | I9: Normale; programmazione; regolazione / attrezzamento; regolazione. | J9: 1.2.2 Posizione relativa (può generare zone di schiacciamento, di cesoiamento, di impigliamento, ecc. quando le parti sono in movimento) 7.2.9 Guasto o disfunzione nel sistema di comando (avviamento inatteso, fuorigiri inatteso) 7.2.10 Guasto nel circuito di comando | K9: 3 | L9: 5 | M9: 3 | N9: 5 | O9: =IF(COUNT(L9:N9)=3,SUM(L9:N9),"") -> 13 | P9: =IF(OR(K9="",O9=""),"",INDEX(Metodo!$C$6:$G$9,MATCH(K9,Metodo!$B$6:$B$9,0),MATCH(O9,Metodo!$C$5:$G$5,1))) -> Richieste | Q9: L’Impianto di smerigliatura e lucidatura rubinetteria viene progettato per eseguire in modo automatico le operazioni di smerigliatura e, successivamente, di pulitura di componenti di rubinetteria. L'impianto sarà realizzato con due zone di lavoro, di smerigliatura e di pulitura, ognuna con una propria cabina di protezione e fonti di alimentazione. L’impianto sarà quindi dotato, per ciascuna zona, di un sistema di comando e controllo che gestisce dispositivi o apparecchiature elettriche e pneumatiche della propria zona. Le seguenti parti del sistema di comando svolgeranno funzioni di sicurezza: - Arresto di emergenza - PLr=d (vedere RESS 1.2.4.3); - Arresto legato alla sicurezza avviato da un mezzo di protezione (interblocco di un riparo mobile) - PLr=d (vedere RESS 1.3.7, 1.4.1 e 1.4.2.2); - Arresto legato alla sicurezza avviato da un mezzo di protezione (barriera fotoelettrica) - PLr=d (vedere RESS 1.3.7, 1.4.1 e 1.4.3); - Ripristino manuale - PLr=d (vedere RESS 1.2.2 e 1.2.3); - Avvio/riavvio - PLr=d (vedere RESS 1.2.2 e 1.2.3); - Dispositivo di consenso - interruttore di abilitazione "uomo morto" a 3 posizioni su ciascun terminale portatile - PLr=d (vedere RESS 1.2.5); - Modalità di comando - PLr=d (vedere RESS 1.2.5). Tutte le funzioni di sicurezza sopra descritte verranno realizzate con componenti e un’architettura tale da ottenere o superare il Performance Level richiesto (PLr). Vedere la "Relazione sistemi di comando legati alla sicurezza secondo EN ISO 13849-1/-2" nella sezione "Analisi per la sicurezza" del Fascicolo Tecnico. Tutte le apparecchiature utilizzate saranno adatte agli ambienti industriali e inserite all'interno di un armadio in carpenteria metallica. Inoltre, e per una maggior sicurezza: - Tutti i cablaggi relativi ai segnali analogici verranno realizzati con cavi schermati (salvo che il costruttore del prodotto non lo richieda); - Le apparecchiature di potenza ed i relativi cablaggi verranno, per quanto possibile, separati dalle apparecchiature elettroniche di comando o di sicurezza; - Tutte le parti metalliche strutturali del quadro elettrico e le apparecchiature che lo prevedono verranno collegate al circuito equipotenziale di terra; - Una delle due fasi di alimentazione del circuito ausiliario verrà collegata al circuito equipotenziale. L'impianto NON utilizzerà di dispositivi senza cavo. | S9: 3 | T9: 2 | U9: 1 | V9: 1 | W9: =IF(COUNT(T9:V9)=3,SUM(T9:V9),"") -> 4 | X9: =IF(OR(S9="",W9=""),"",INDEX(Metodo!$C$6:$G$9,MATCH(S9,Metodo!$B$6:$B$9,0),MATCH(W9,Metodo!$C$5:$G$5,1))) -> OK | Y9: Norme A: EN ISO 12100 Norme B: EN ISO 13849-1; IEC/EN 62061; EN 60204-1 | Norme: ISO/TR 14121-2
A10: LIB-009 | B10: 1.2.2 | C10: Dispositivi di comando | D10: VRQ-001 | E10: Impianto | F10: Sistema di comando | G10: Sempre | H10: Parti mobili e attive dell'impianto | I10: Normale; programmazione; sblocco anomalie. | J10: 7.2.10 Guasto nel circuito di comando 9.1.3 Pericoli provocati da inadeguata progettazione o identificazione dei comandi manuali 9.1.6 Posizionamento inadeguato degli organi di comando manuali | K10: 2 | L10: 5 | M10: 2 | N10: 3 | O10: =IF(COUNT(L10:N10)=3,SUM(L10:N10),"") -> 10 | P10: =IF(OR(K10="",O10=""),"",INDEX(Metodo!$C$6:$G$9,MATCH(K10,Metodo!$B$6:$B$9,0),MATCH(O10,Metodo!$C$5:$G$5,1))) -> Suggerite | Q10: L’Impianto di smerigliatura e lucidatura rubinetteria viene progettato per eseguire in modo automatico le operazioni di smerigliatura e, successivamente, di pulitura di componenti di rubinetteria. L'impianto sarà realizzato con due zone di lavoro, di smerigliatura e di pulitura, ognuna con una propria cabina di protezione e fonti di alimentazione. L’impianto sarà quindi dotato, per ciascuna zona, di sistema di comando. La zona di smerigliatura sarà equipaggiata con: - Un quadro elettrico di alimentazione; - Un pannello operatore di interfaccia uomo-macchina; - Un quadro controller con terminale di programmazione del robot A; - Un quadro controller con terminale di programmazione del robot B; - Un quadro controller con terminale di programmazione del robot C; - Una pulsantiera di comando locale in corrispondenza della stazione di carico; - Una pulsantiera di comando locale in corrispondenza del trasportatore di scarico; - Una pulsantiera di comando locale del primo dispositivo di scambio robot (all'interno della cabina); - Una pulsantiera di comando locale del secondo dispositivo di scambio robot (all'interno della cabina); - Una serie di pulsanti di emergenza dislocati in vari punti dell'impianto anche all'interno della cabina di protezione (vedere RESS 1.2.4.3). La zona di pulitura sarà equipaggiata con: - Un quadro elettrico di alimentazione; - Un pannello operatore di interfaccia uomo-macchina; - Un pannello operatore mobile; - Un pedale di comando in corrispondenza della stazione di carico/scarico; - Una serie di pulsanti di emergenza dislocati in vari punti all'interno della cabina di protezione (vedere RESS 1.2.4.3). Per quanto riguarda i terminali portatili (di ciascun robot della zona di smerigliatura e quello dedicato alla zona di pulitura), questi saranno componenti di commercio. In generale: - Tutti i dispositivi di comando saranno posti in un involucro per parti elettriche adatto all’ambiente di utilizzo. - L'altezza da terra dei dispositivi di comando sarà compresa fra i 600 e i 1700 mm dal pavimento. - Tutti i dispositivi di comando e segnalazione avranno un'etichetta con riportata la funzione e la zona controllata. - I dispositivi di comando posti sulle varie pulsantiere saranno quelli utili alle operazioni che l'operatore dovrà svolgere in tale postazione. - I quadri elettrici delle due zone saranno posti ciascuno in corrispondenza della propria zona (accostati alla cabina di protezione). - Qualora i quadri elettrici avranno dispositivi di comando necessari all'avviamento e all'arresto della zona (come il selettore modale e di sblocco porte), essi saranno ubicati in modo da: aver visione della zona interna protetta ed essere di facile accesso. - Quando un dispositivo di comando consentirà varie azioni differenti, vale a dire se la sua azione non è univoca, l'azione comandata sarà chiaramente indicata e, se necessario, confermata. - Gli indicatori di stato delle zone di lavoro saranno ubicati in modo tale che l'operatore addetto alla conduzione dalla sua postazione di lavoro principale (scarico nastro e carico/scarico tavola rotante) possa averne visione. Dalle postazioni principali di conduzione, l'operatore potrà verificare che all'interno delle zone protette non vi siano persone. I comandi di ripristino e di avviamento, quindi, saranno ubicati dove l’operatore avrà una visione chiara e libera dello spazio protetto. Nel caso in cui il layout delle zone di lavoro è tale da consentire ad un operatore di essere nascosto alla vista dalla postazione dove avviene il ripristino e avvio, verranno installati dei dispositivi aggiuntivi di ripristino a tempo limitato all’interno della zona protetta: uno tra le due porte posteriori e uno tra le due porta anteriori. Per il ripristino della macchina sarà necessario premere uno dei due dispositivi di ripristino interni e, subito dopo (entro il lasso di tempo necessario a raggiungerlo) il secondo comando di ripristino esterno. Vedere schemi elettrici all'interno del Fascicolo tecnico. | R10: Nelle istruzioni dell'impianto si riporterà: - la descrizione di ogni dispositivo di comando; - il significato di ogni spia luminosa; - le istruzioni del software (in allegato). | S10: 2 | T10: 5 | U10: 1 | V10: 1 | W10: =IF(COUNT(T10:V10)=3,SUM(T10:V10),"") -> 7 | X10: =IF(OR(S10="",W10=""),"",INDEX(Metodo!$C$6:$G$9,MATCH(S10,Metodo!$B$6:$B$9,0),MATCH(W10,Metodo!$C$5:$G$5,1))) -> OK | Y10: Norme A: EN ISO 12100 Norme B: EN 981; EN 894-1; EN 894-3; EN 894-4 | Norme: ISO/TR 14121-2
A11: LIB-010 | B11: 1.2.3 | C11: Avviamento | D11: VRQ-001 | E11: Impianto | F11: Sistema di comando | G11: Sempre | I11: Normale. | O11: =IF(COUNT(L11:N11)=3,SUM(L11:N11),"") | P11: =IF(OR(K11="",O11=""),"",INDEX(Metodo!$C$6:$G$9,MATCH(K11,Metodo!$B$6:$B$9,0),MATCH(O11,Metodo!$C$5:$G$5,1))) | Q11: L’Impianto di smerigliatura e lucidatura rubinetteria viene progettato per eseguire in modo automatico le operazioni di smerigliatura e, successivamente, di pulitura di componenti di rubinetteria. L'impianto sarà realizzato con due zone di lavoro, di smerigliatura e di pulitura, ognuna con una propria cabina di protezione e fonti di alimentazione. L’impianto sarà quindi dotato, per ciascuna zona, di un sistema di comando e controllo che gestisce dispositivi o apparecchiature elettriche e pneumatiche della propria zona. Vedere la scheda di valutazione VRQ-100 del presente RESS per la zona di smerigliatura. Vedere la scheda di valutazione VRQ-200 del presente RESS per la zona di pulitura. | R11: Nelle istruzioni dell'impianto vengono riportate le procedure per la messa in tensione e l'avviamento dell'impianto. | W11: =IF(COUNT(T11:V11)=3,SUM(T11:V11),"") | X11: =IF(OR(S11="",W11=""),"",INDEX(Metodo!$C$6:$G$9,MATCH(S11,Metodo!$B$6:$B$9,0),MATCH(W11,Metodo!$C$5:$G$5,1))) | Y11: Norme A: EN ISO 12100 Norme B: EN ISO 14118 | Norme: ISO/TR 14121-2 | Z11: Scheda descrittiva, senza stima del rischio.
A12: LIB-011 | B12: 1.2.3 | C12: Avviamento | D12: VRQ-100 | E12: Smerigliatura | F12: Sistema di comando | G12: Sempre | H12: Tutte le parti mobili e attive della zona di smerigliatura | I12: Normale. | J12: 1.2.2 Posizione relativa (può generare zone di schiacciamento, di cesoiamento, di impigliamento, ecc. quando le parti sono in movimento) 7.2.2 Avviamento inatteso | K12: 3 | L12: 5 | M12: 3 | N12: 3 | O12: =IF(COUNT(L12:N12)=3,SUM(L12:N12),"") -> 11 | P12: =IF(OR(K12="",O12=""),"",INDEX(Metodo!$C$6:$G$9,MATCH(K12,Metodo!$B$6:$B$9,0),MATCH(O12,Metodo!$C$5:$G$5,1))) -> Richieste | Q12: ZONA DI SMERIGLIATURA Per abilitare la zona di smerigliatura al funzionamento sarà necessario, dopo la messa in tensione, usare il comando di “RIPRISTINO SMERIGLIATURA”. L’avvenuta abilitazione sarà segnalata dall’accensione della spia integrata nel pulsante stesso. Il ripristino della zona di smerigliatura sarà possibile solo se tutte le porte di accesso alla zona di lavoro di smerigliatura saranno chiuse e bloccate e non vi saranno pulsanti di emergenza di zona premuti. A questo punto, se non ci sono anomalie da resettare e/o parti della zona da azzerare (ovvero da portare nella posizione prevista di inizio ciclo): - con selettore modale su “AUT” e programma o ordine di lavoro caricato sul pannello operatore, sarà possibile avviare il ciclo di lavoro automatico premendo il pulsante “INIZIO CICLO SMERIGLIATURA"; - con selettore modale su "MAN" sarà possibile muovere una specifica stazione di lavoro, attraverso il pannello operatore e appositi dispositivi di comando. Ponendo il selettore modale su "SBLOCCA PORTE", tutte le parti della zona di smerigliatura non potranno attivarsi, e le porte interbloccate verranno sbloccate in modo che l’operatore possa accedere alla zona di smerigliatura. Vedere RESS 1.3.7. Con selettore modale su "SBLOCCA PORTE" sarà possibile utilizzare il terminale portatile di un robot, impostandolo in modalità manuale (tramite selettore a chiave -vedere RESS 1.2.5), per eseguire la programmazione del gruppo di smerigliatura abilitato (tutti gli altri elementi della zona di smerigliatura saranno in arresto sicuro). Vi sarà un unico dispositivo di comando per l'avviamento della zona di smerigliatura. L’avviamento della zona di smerigliatura dovrà essere ri-eseguita ogni volta che si è verificata un’emergenza o grave anomalia o le porte interbloccate sono state sbloccate. Vi sarà un unico dispositivo di comando per il ripristino della zona di smerigliatura, posto in corrispondenza della postazione di comando dove l'operatore potrà avere il controllo dell'intera zona. | S12: 3 | T12: 2 | U12: 1 | V12: 1 | W12: =IF(COUNT(T12:V12)=3,SUM(T12:V12),"") -> 4 | X12: =IF(OR(S12="",W12=""),"",INDEX(Metodo!$C$6:$G$9,MATCH(S12,Metodo!$B$6:$B$9,0),MATCH(W12,Metodo!$C$5:$G$5,1))) -> OK | Y12: Norme A: EN ISO 12100 Norme B: EN ISO 14118 | Norme: ISO/TR 14121-2
A13: LIB-012 | B13: 1.2.3 | C13: Avviamento | D13: VRQ-200 | E13: Pulitura | F13: Sistema di comando | G13: Sempre | H13: Tutte le parti mobili e attive della zona di pulitura | I13: Normale. | J13: 1.2.2 Posizione relativa (può generare zone di schiacciamento, di cesoiamento, di impigliamento, ecc. quando le parti sono in movimento) 7.2.2 Avviamento inatteso | K13: 3 | L13: 5 | M13: 3 | N13: 3 | O13: =IF(COUNT(L13:N13)=3,SUM(L13:N13),"") -> 11 | P13: =IF(OR(K13="",O13=""),"",INDEX(Metodo!$C$6:$G$9,MATCH(K13,Metodo!$B$6:$B$9,0),MATCH(O13,Metodo!$C$5:$G$5,1))) -> Richieste | Q13: ZONA DI PULITURA Per abilitare la zona di pulitura al funzionamento sarà necessario, dopo la messa in tensione, usare il comando di “RIPRISTINO PULITURA”. L’avvenuta abilitazione sarà segnalata dall’accensione della spia integrata nel pulsante stesso. Il ripristino della zona di pulitura sarà possibile solo se tutte le porte di accesso alla zona di lavoro di pulitura saranno chiuse e bloccate, non vi saranno pulsanti di emergenza di zona premuti, la barriera fotoelettrica a protezione del varco di carico/scarico pezzi non sarà violata. A questo punto, se non ci sono anomalie da resettare e/o parti della zona da azzerare (ovvero da portare nella posizione prevista di inizio ciclo): - con selettore modale su “AUT” e programma o ordine di lavoro caricato sul pannello operatore, sarà possibile avviare il ciclo di lavoro automatico premendo il pulsante “INIZIO CICLO PULITURA"; - con selettore modale su "MAN" sarà possibile muovere una specifica stazione di lavoro, attraverso il pannello operatore e appositi dispositivi di comando. Ponendo il selettore modale su "SBLOCCA PORTE", tutte le parti della zona di pulitura non potranno attivarsi, e le porte interbloccate verranno sbloccate in modo che l’operatore possa accedere alla zona di pulitura. Durante il funzionamento, le parti mobili subiranno un immediato arresto. Con selettore modale su "SBLOCCA PORTE" sarà possibile utilizzare il terminale portatile di zona e, una volta inserite le credenziali di utente di alto livello (in possesso a personale specificatamente addestrato), sarà possibile eseguire le operazioni per la programmazione (vedere RESS 1.2.5). Vi sarà un unico dispositivo di comando per l'avviamento della zona di pulitura. L’avviamento della zona di pulitura dovrà essere ri-eseguita ogni volta che si è verificata un’emergenza o grave anomalia o le porte interbloccate sono state sbloccate. Vi sarà un unico dispositivo di comando per il ripristino della zona di pulitura, posto in corrispondenza della postazione di comando dove l'operatore potrà avere il controllo dell'intera zona. | S13: 3 | T13: 2 | U13: 1 | V13: 1 | W13: =IF(COUNT(T13:V13)=3,SUM(T13:V13),"") -> 4 | X13: =IF(OR(S13="",W13=""),"",INDEX(Metodo!$C$6:$G$9,MATCH(S13,Metodo!$B$6:$B$9,0),MATCH(W13,Metodo!$C$5:$G$5,1))) -> OK | Y13: Norme A: EN ISO 12100 Norme B: EN ISO 14118 | Norme: ISO/TR 14121-2
A14: LIB-013 | B14: 1.2.4.1 | C14: Arresto normale | D14: VRQ-001 | E14: Impianto | F14: Sistema di comando | G14: Sempre | I14: Normale. | O14: =IF(COUNT(L14:N14)=3,SUM(L14:N14),"") | P14: =IF(OR(K14="",O14=""),"",INDEX(Metodo!$C$6:$G$9,MATCH(K14,Metodo!$B$6:$B$9,0),MATCH(O14,Metodo!$C$5:$G$5,1))) | Q14: L’Impianto di smerigliatura e lucidatura rubinetteria viene progettato per eseguire in modo automatico le operazioni di smerigliatura e, successivamente, di pulitura di componenti di rubinetteria. L'impianto sarà realizzato con due zone di lavoro, di smerigliatura e di pulitura, ognuna con una propria cabina di protezione e fonti di alimentazione. L’impianto sarà quindi dotato, per ciascuna zona, di un sistema di comando e controllo che gestisce dispositivi o apparecchiature elettriche e pneumatiche della propria zona. Vedere la scheda di valutazione VRQ-100 del presente RESS per la zona di smerigliatura. Vedere la scheda di valutazione VRQ-200 del presente RESS per la zona di pulitura. | W14: =IF(COUNT(T14:V14)=3,SUM(T14:V14),"") | X14: =IF(OR(S14="",W14=""),"",INDEX(Metodo!$C$6:$G$9,MATCH(S14,Metodo!$B$6:$B$9,0),MATCH(W14,Metodo!$C$5:$G$5,1))) | Y14: Norme A: EN ISO 12100 Norme B: EN 60204-1 | Norme: ISO/TR 14121-2 | Z14: Scheda descrittiva, senza stima del rischio.
A15: LIB-014 | B15: 1.2.4.1 | C15: Arresto normale | D15: VRQ-100 | E15: Smerigliatura | F15: Sistema di comando | G15: Sempre | H15: Tutte le parti mobili e attive della zona di smerigliatura | I15: Normale. | J15: 1.2.2 Posizione relativa (può generare zone di schiacciamento, di cesoiamento, di impigliamento, ecc. quando le parti sono in movimento) 1.2.4 Massa e velocità (energia cinetica di elementi in movimento controllato o non controllato) 7.2.3 Mancato arresto, se il comando è già stato dato | K15: 2 | L15: 5 | M15: 3 | N15: 3 | O15: =IF(COUNT(L15:N15)=3,SUM(L15:N15),"") -> 11 | P15: =IF(OR(K15="",O15=""),"",INDEX(Metodo!$C$6:$G$9,MATCH(K15,Metodo!$B$6:$B$9,0),MATCH(O15,Metodo!$C$5:$G$5,1))) -> Richieste | Q15: La zona di smerigliatura avrà dispositivi di comando per l'arresto del ciclo di lavoro della zona, in corrispondenza di tutte le postazioni di conduzione dell'operatore (quadro elettrico, pulsantiera a fine trasportatore di scarico, ecc.) Una volta dato il comando di arresto, tutte le stazioni di lavoro della zona di smerigliatura termineranno la fase lavorativa in corso e si porteranno in posizione di zero, in modo che il ciclo possa essere ripreso immediatamente con il pulsante "INIZIO CICLO", se le condizioni originali non vengono alterate. | R15: Nelle istruzioni dell'impianto verranno date indicazioni sulle modalità di arresto. | S15: 2 | T15: 2 | U15: 1 | V15: 1 | W15: =IF(COUNT(T15:V15)=3,SUM(T15:V15),"") -> 4 | X15: =IF(OR(S15="",W15=""),"",INDEX(Metodo!$C$6:$G$9,MATCH(S15,Metodo!$B$6:$B$9,0),MATCH(W15,Metodo!$C$5:$G$5,1))) -> OK | Y15: Norme A: EN ISO 12100 Norme B: EN 60204-1 | Norme: ISO/TR 14121-2
A16: LIB-015 | B16: 1.2.4.1 | C16: Arresto normale | D16: VRQ-200 | E16: Pulitura | F16: Sistema di comando | G16: Sempre | H16: Tutte le parti mobili e attive della zona di pulitura | I16: Normale. | J16: 1.2.2 Posizione relativa (può generare zone di schiacciamento, di cesoiamento, di impigliamento, ecc. quando le parti sono in movimento) 1.2.4 Massa e velocità (energia cinetica di elementi in movimento controllato o non controllato) 7.2.3 Mancato arresto, se il comando è già stato dato | K16: 2 | L16: 5 | M16: 3 | N16: 3 | O16: =IF(COUNT(L16:N16)=3,SUM(L16:N16),"") -> 11 | P16: =IF(OR(K16="",O16=""),"",INDEX(Metodo!$C$6:$G$9,MATCH(K16,Metodo!$B$6:$B$9,0),MATCH(O16,Metodo!$C$5:$G$5,1))) -> Richieste | Q16: La zona di pulitura avrà dispositivi di comando per l'arresto del ciclo di lavoro della zona, in corrispondenza di tutte le postazioni di conduzione dell'operatore (pannello di comando sulla postazione di carico/scarico, ecc.). Una volta dato il comando, tutte le stazioni di lavoro della zona di pulitura termineranno la fase lavorativa in corso e si porteranno in posizione di zero, in modo che il ciclo possa essere ripreso immediatamente con il pulsante "INIZIO CICLO", se le condizioni originali non vengono alterate. | R16: Nelle istruzioni dell'impianto verranno date indicazioni sulle modalità di arresto. | S16: 2 | T16: 2 | U16: 1 | V16: 1 | W16: =IF(COUNT(T16:V16)=3,SUM(T16:V16),"") -> 4 | X16: =IF(OR(S16="",W16=""),"",INDEX(Metodo!$C$6:$G$9,MATCH(S16,Metodo!$B$6:$B$9,0),MATCH(W16,Metodo!$C$5:$G$5,1))) -> OK | Y16: Norme A: EN ISO 12100 Norme B: EN 60204-1 | Norme: ISO/TR 14121-2
A17: LIB-016 | B17: 1.2.4.3 | C17: Arresto di emergenza | D17: VRQ-001 | E17: Impianto | F17: Sistema di comando | G17: Sempre | I17: Normale; manutenzione; programmazione; regolazione. | O17: =IF(COUNT(L17:N17)=3,SUM(L17:N17),"") | P17: =IF(OR(K17="",O17=""),"",INDEX(Metodo!$C$6:$G$9,MATCH(K17,Metodo!$B$6:$B$9,0),MATCH(O17,Metodo!$C$5:$G$5,1))) | Q17: L’Impianto di smerigliatura e lucidatura rubinetteria viene progettato per eseguire in modo automatico le operazioni di smerigliatura e, successivamente, di pulitura di componenti di rubinetteria. L'impianto sarà realizzato con due zone di lavoro, di smerigliatura e di pulitura, ognuna con una propria cabina di protezione e fonti di alimentazione. L’impianto sarà quindi dotato, per ciascuna zona, di un sistema di comando e controllo che gestisce dispositivi o apparecchiature elettriche e pneumatiche della propria zona. Vedere la scheda di valutazione VRQ-100 del presente RESS per la zona di smerigliatura. Vedere la scheda di valutazione VRQ-200 del presente RESS per la zona di pulitura. | W17: =IF(COUNT(T17:V17)=3,SUM(T17:V17),"") | X17: =IF(OR(S17="",W17=""),"",INDEX(Metodo!$C$6:$G$9,MATCH(S17,Metodo!$B$6:$B$9,0),MATCH(W17,Metodo!$C$5:$G$5,1))) | Y17: Norme A: EN ISO 12100 Norme B: EN ISO 13850; EN 60947-5-5; EN 60204-1 | Norme: ISO/TR 14121-2 | Z17: Scheda descrittiva, senza stima del rischio.
A18: LIB-017 | B18: 1.2.4.3 | C18: Arresto di emergenza | D18: VRQ-100 | E18: Smerigliatura | F18: Sistema di comando | G18: Sempre | H18: Tutte le parti mobili e attive della zona di smerigliatura | I18: Normale; manutenzione; programmazione; regolazione / attrezzamento. | J18: 1.1.1 Pericolo di schiacciamento 1.1.2 Pericolo di cesoiamento 1.1.3 Pericolo di taglio o di sezionamento 1.1.4 Pericolo di impigliamento 1.1.5 Pericolo di trascinamento o d'intrappolamento 1.1.6 Pericolo di urto 1.1.8 Pericolo di attrito o di abrasione 1.2.2 Posizione relativa (può generare zone di schiacciamento, di cesoiamento, di impigliamento, ecc. quando le parti sono in movimento) | K18: 3 | L18: 4 | M18: 3 | N18: 5 | O18: =IF(COUNT(L18:N18)=3,SUM(L18:N18),"") -> 12 | P18: =IF(OR(K18="",O18=""),"",INDEX(Metodo!$C$6:$G$9,MATCH(K18,Metodo!$B$6:$B$9,0),MATCH(O18,Metodo!$C$5:$G$5,1))) -> Richieste | Q18: ZONA DI SMERIGLIATURA La zona di smerigliatura sarà dotata di diversi pulsanti di arresto di emergenza, ubicati in corrispondenza della pulsantiera/quadro da cui è possibile l'avviamento di zona, sulla pulsantiera di comando della postazione di carico pallet, su ciascun terminale portatile e su ogni smerigliatrice a nastro (all'interno della zona protetta). I pulsanti di emergenza saranno ad autoritenuta, di colore rosso su fondo giallo (per quanto possibile). Premendo un pulsante di emergenza, tutte le parti della zona di smerigliatura si arresteranno immediatamente e le porte di accesso alla zona di lavoro di smerigliatura verranno sbloccate. In questa condizione il circuito pneumatico non verrà scaricato dalla pressione, anche per garantire che i nastri abrasivi nelle smerigliatrici rimangano in posizione tesa, e che siano mantenuti i comandi delle pinze di presa dei pezzi. Il ripristino del pulsante di emergenza premuto non comporterà alcun movimento o avviamento. A seguito di un'emergenza sarà necessario ripetere la procedura di avviamento della zona di smerigliatura ripristinando la sicurezza con l'apposito comando di ripristino manuale (vedere RESS 1.2.3). La funzione dei pulsanti di arresto di emergenza sarà sempre disponibile qualsiasi sia la modalità di funzionamento della zona di smerigliatura. I pulsanti di emergenza, insieme al relativo circuito di comando, realizzano una funzione di sicurezza. Vedere la sezione "Schemi circuitali" del fascicolo tecnico. | R18: Nelle istruzioni dell'impianto sarà riportata l'ubicazione dei pulsanti di arresto di emergenza della zona di smerigliatura. | S18: 3 | T18: 2 | U18: 1 | V18: 1 | W18: =IF(COUNT(T18:V18)=3,SUM(T18:V18),"") -> 4 | X18: =IF(OR(S18="",W18=""),"",INDEX(Metodo!$C$6:$G$9,MATCH(S18,Metodo!$B$6:$B$9,0),MATCH(W18,Metodo!$C$5:$G$5,1))) -> OK | Y18: Norme A: EN ISO 12100 Norme B: EN ISO 13850; EN 60947-5-5; EN 60204-1 | Norme: ISO/TR 14121-2
A19: LIB-018 | B19: 1.2.4.3 | C19: Arresto di emergenza | D19: VRQ-200 | E19: Pulitura | F19: Sistema di comando | G19: Sempre | H19: Tutte le parti mobili e attive della zona di pulitura | I19: Normale; manutenzione; programmazione; regolazione / attrezzamento. | J19: 1.1.1 Pericolo di schiacciamento 1.1.2 Pericolo di cesoiamento 1.1.3 Pericolo di taglio o di sezionamento 1.1.4 Pericolo di impigliamento 1.1.5 Pericolo di trascinamento o d'intrappolamento 1.1.6 Pericolo di urto 1.1.8 Pericolo di attrito o di abrasione 1.2.2 Posizione relativa (può generare zone di schiacciamento, di cesoiamento, di impigliamento, ecc. quando le parti sono in movimento) | K19: 3 | L19: 4 | M19: 3 | N19: 5 | O19: =IF(COUNT(L19:N19)=3,SUM(L19:N19),"") -> 12 | P19: =IF(OR(K19="",O19=""),"",INDEX(Metodo!$C$6:$G$9,MATCH(K19,Metodo!$B$6:$B$9,0),MATCH(O19,Metodo!$C$5:$G$5,1))) -> Richieste | Q19: ZONA DI PULITURA La zona di pulitura sarà dotata di diversi pulsanti di arresto di emergenza, ubicati in corrispondenza della pulsantiera/quadro da cui è possibile l'avviamento di zona, in corrispondenza della postazione di carico/scarico pezzi, sul terminale portatile e all'interno della zona di pulitura, in prossimità di ciascuna unità CNC. I pulsanti di emergenza saranno ad autoritenuta, di colore rosso su fondo giallo (per quanto possibile). Premendo un pulsante di emergenza, tutte le parti della zona di pulitura si arresteranno e le porte di accesso alla zona di lavoro di pulitura verranno sbloccate. In questa condizione il circuito pneumatico non verrà scaricato dalla pressione per mantenere in presa i pezzi sulle pinze ad azione positiva. Il ripristino del pulsante di emergenza premuto non comporterà alcun movimento o avviamento. A seguito di un'emergenza sarà necessario ripetere la procedura di avviamento della zona di pulitura ripristinando la sicurezza con l'apposito comando di ripristino manuale (vedere RESS 1.2.3). La funzione dei pulsanti di arresto di emergenza sarà sempre disponibile qualsiasi sia la modalità di funzionamento della zona di pulitura. I pulsanti di emergenza, insieme al relativo circuito di comando, realizzano una funzione di sicurezza. Vedere la sezione "Schemi circuitali" del fascicolo tecnico. | S19: 3 | T19: 2 | U19: 1 | V19: 1 | W19: =IF(COUNT(T19:V19)=3,SUM(T19:V19),"") -> 4 | X19: =IF(OR(S19="",W19=""),"",INDEX(Metodo!$C$6:$G$9,MATCH(S19,Metodo!$B$6:$B$9,0),MATCH(W19,Metodo!$C$5:$G$5,1))) -> OK | Y19: Norme A: EN ISO 12100 Norme B: EN ISO 13850; EN 60947-5-5; EN 60204-1 | Norme: ISO/TR 14121-2
A20: LIB-019 | B20: 1.2.5 | C20: Selezione del modo di comando o di funzionamento | D20: VRQ-001 | E20: Impianto | F20: Sistema di comando | G20: Sempre | I20: Normale; sblocco anomalie; regolazione / attrezzamento; programmazione. | O20: =IF(COUNT(L20:N20)=3,SUM(L20:N20),"") | P20: =IF(OR(K20="",O20=""),"",INDEX(Metodo!$C$6:$G$9,MATCH(K20,Metodo!$B$6:$B$9,0),MATCH(O20,Metodo!$C$5:$G$5,1))) | Q20: L’Impianto di smerigliatura e lucidatura rubinetteria viene progettato per eseguire in modo automatico le operazioni di smerigliatura e, successivamente, di pulitura di componenti di rubinetteria. L'impianto sarà realizzato con due zone di lavoro, di smerigliatura e di pulitura, ognuna con una propria cabina di protezione e fonti di alimentazione. Vedere la scheda di valutazione VRQ-100 del presente RESS per la zona di smerigliatura. Vedere la scheda di valutazione VRQ-200 del presente RESS per la zona di pulitura. | W20: =IF(COUNT(T20:V20)=3,SUM(T20:V20),"") | X20: =IF(OR(S20="",W20=""),"",INDEX(Metodo!$C$6:$G$9,MATCH(S20,Metodo!$B$6:$B$9,0),MATCH(W20,Metodo!$C$5:$G$5,1))) | Y20: Norme A: EN ISO 12100 Norme B: EN ISO 13849-1; EN 62061; EN 60204-1 | Norme: ISO/TR 14121-2 | Z20: Scheda descrittiva, senza stima del rischio.
A21: LIB-020 | B21: 1.2.5 | C21: Selezione del modo di comando o di funzionamento | D21: VRQ-100 | E21: Smerigliatura | F21: Sistema di comando | G21: Sempre | H21: Tutte le parti mobili e attive della zona di smerigliatura | I21: Normale; programmazione; regolazione / attrezzamento; sblocco anomalie. | J21: 1.1.1 Pericolo di schiacciamento 1.1.2 Pericolo di cesoiamento 1.1.3 Pericolo di taglio o di sezionamento 1.1.4 Pericolo di impigliamento 1.1.5 Pericolo di trascinamento o d'intrappolamento 1.1.6 Pericolo di urto 1.1.8 Pericolo di attrito o di abrasione 1.2.2 Posizione relativa (può generare zone di schiacciamento, di cesoiamento, di impigliamento, ecc. quando le parti sono in movimento) | K21: 3 | L21: 5 | M21: 3 | N21: 5 | O21: =IF(COUNT(L21:N21)=3,SUM(L21:N21),"") -> 13 | P21: =IF(OR(K21="",O21=""),"",INDEX(Metodo!$C$6:$G$9,MATCH(K21,Metodo!$B$6:$B$9,0),MATCH(O21,Metodo!$C$5:$G$5,1))) -> Richieste | Q21: ZONA DI SMERIGLIATURA La selezione del modo di funzionamento avrà la priorità su tutti gli altri comandi, salvo l’arresto d’emergenza. La selezione del modo di funzionamento sarà mediante selettori a chiave. - Modo AUTOMATICO: la zona di smerigliatura funzionerà seguendo l’ordine di lavoro (programma) impostato sull’interfaccia operatore. Il funzionamento in AUTOMATICO sarà consentito sole se tutte le porte interbloccate della cabina della zona di smerigliatura saranno chiuse e se non saranno presenti condizioni di allarme. Il modo AUTOMATICO sarà quello usato per la produzione. - Modo MANUALE: la zona di smerigliatura non potrà operare a livello produttivo. Una volta richiamata la pagina specifica di una stazione di lavoro della zona di smerigliatura, sarà possibile eseguire una singola movimentazione. Il funzionamento in MANUALE sarà consentito solo se tutte le porte interbloccate della cabina della zona di smerigliatura saranno chiuse e se non saranno presenti condizioni di allarme. Il modo MANUALE sarà usato per l'azzeramento delle stazioni di lavoro, sblocco anomalie, o riposizionamento in condizioni utili per partire con la produzione. - Modo TEST (SBLOCCA PORTE), che consentirà: - di accedere alla zona di lavoro per eseguire la sostituzione degli utensili o le regolazioni necessarie per cambio codice prodotto da lavorare, in quanto le porte di accesso alla zona di lavoro sono sbloccate e tutte le utenze elettriche sono in arresto sicuro (in questa condizione il circuito pneumatico non viene scaricato dalla pressione). Non è previsto l'uso del terminale portatile dei robot; - (in associazione alla modalità operativa di uno dei robot) la programmazione di una ricetta con il terminale portatile di uno dei robot. Solo per operatori qualificati alla programmazione dei robot e dei gruppi di smerigliatura. Quando il selettore modale è su “SBLOCCA PORTE”, tutte le porte interbloccate di accesso alla zona di lavoro di smerigliatura saranno sbloccate e una volta impostata la modalità manuale del robot con cui si intende operare, sarà possibile utilizzare il relativo terminale portatile, stando all'interno della cabina di protezione della zona di smerigliatura (porte sbloccate) e con la possibilità di osservare la posizione delle utenze. Il selettore modale dei robot sarà quello del quadro controller e quindi di commercio. I robot saranno certificati ai sensi della norma EN ISO 10218-1 e quindi i modi di funzionamento e il terminale portatile con il relativo dispositivo di abilitazione “uomo morto” a tre posizioni saranno quelli previsti da norma. In modo TEST (SBLOCCO PORTE di zona + T1 del robot) l'operatore addetto alla programmazione, stando all'interno della zona di lavoro di smerigliatura e con dispositivo di abilitazione premuto, potrà: - Movimentare un solo asse di un solo elemento alla volta del solo gruppo di smerigliatura attivo e a velocità ridotta; - Movimentare il robot antropomorfo ad una velocità ridotta (massimo 250 mm/sec). Quando un robot sarà in modalità manuale gli altri robot e tutte le altre stazioni di lavoro saranno in arresto sicuro. Qualora i robot abbiano la modalità manuale ad alta velocità T2 verranno adottate le ulteriori condizioni di sicurezza indicate al RESS 1.3.7, VRQ-121. Il cambio della modalità di funzionamento durante il ciclo di lavoro automatico comporterà un suo arresto. Lo "SBLOCCO PORTE" comporterà il ripristino manuale e riavviamento del ciclo di lavoro. Si daranno misure di protezione mediante le istruzioni. I selettori modali, insieme al relativo circuito di comando, realizzeranno una funzione di sicurezza. I dispositivi "uomo morto" di abilitazione presenti sui terminali portatili realizzeranno, insieme al relativo circuito di comando, una funzione di sicurezza. | R21: Nelle istruzioni dell’impianto si riporterà: - L’obbligo di portare con sé la chiave del selettore modale quando si accede alla zona di lavoro di smerigliatura. - Quando si accede all’area protetta indossare sempre tutti i dispositivi di protezione individuale previsti. - L’obbligo di consegnare la chiave del selettore modale dei robot al personale qualificato alla programmazione dei robot. - L'avvertenza che solo personale addestrato può utilizzare uno dei terminali portatili per la movimentazione delle parti della zona di smerigliatura all’interno dell’area protetta. - L'avvertenza che, durante le manovre in test, non ci si deve mai posizionare all’interno dello spazio di azione della stazione di lavoro o dei robot. Mantenersi sempre a distanza di sicurezza. - L'avvertenza che, durante i TEST, è necessario porsi al di fuori della potenziale linea di proiezione sia del pezzo in lavorazione (qualora dovesse sfuggire dalla presa della pinza porta-pezza), sia del materiale asportato o degli utensili (nastri abrasivi). | S21: 3 | T21: 4 | U21: 2 | V21: 1 | W21: =IF(COUNT(T21:V21)=3,SUM(T21:V21),"") -> 7 | X21: =IF(OR(S21="",W21=""),"",INDEX(Metodo!$C$6:$G$9,MATCH(S21,Metodo!$B$6:$B$9,0),MATCH(W21,Metodo!$C$5:$G$5,1))) -> Suggerite | Y21: Norme A: EN ISO 12100 Norme B: EN ISO 13849-1; EN 62061; EN 60204-1 | Norme: ISO/TR 14121-2 | Z21: Il rischio finale non è in area verde: verificare se servono altre misure o motivare l'accettazione.
A22: LIB-021 | B22: 1.2.5 | C22: Selezione del modo di comando o di funzionamento | D22: VRQ-200 | E22: Pulitura | F22: Sistema di comando | G22: Sempre | H22: Tutte le parti mobili e attive della zona di pulitura | I22: Normale; programmazione; regolazione / attrezzamento; sblocco anomalie. | J22: 1.1.1 Pericolo di schiacciamento 1.1.2 Pericolo di cesoiamento 1.1.3 Pericolo di taglio o di sezionamento 1.1.4 Pericolo di impigliamento 1.1.5 Pericolo di trascinamento o d'intrappolamento 1.1.6 Pericolo di urto 1.1.8 Pericolo di attrito o di abrasione 1.2.2 Posizione relativa (può generare zone di schiacciamento, di cesoiamento, di impigliamento, ecc. quando le parti sono in movimento) | K22: 3 | L22: 5 | M22: 3 | N22: 5 | O22: =IF(COUNT(L22:N22)=3,SUM(L22:N22),"") -> 13 | P22: =IF(OR(K22="",O22=""),"",INDEX(Metodo!$C$6:$G$9,MATCH(K22,Metodo!$B$6:$B$9,0),MATCH(O22,Metodo!$C$5:$G$5,1))) -> Richieste | Q22: ZONA DI PULITURA La selezione del modo di funzionamento avrà la priorità su tutti gli altri comandi, salvo l’arresto d’emergenza. La selezione del modo di funzionamento sarà mediante un selettore a chiave e password. - Modo AUTOMATICO: la zona di pulitura funzionerà seguendo l’ordine di lavoro (programma) impostato sull’interfaccia operatore. Il funzionamento in AUTOMATICO sarà consentito sole se tutte le porte interbloccate della cabina della zona di pulitura saranno chiuse e se non saranno presenti condizioni di allarme. Il modo AUTOMATICO sarà quello usato per la produzione. - Modo MANUALE: la zona di pulitura non potrà operare a livello produttivo. Una volta richiamata la pagina specifica di una stazione di lavoro della zona di pulitura, sarà possibile eseguire una singola movimentazione. Il funzionamento in MANUALE sarà consentito solo se tutte le porte interbloccate della cabina della zona di pulitura saranno chiuse e se non saranno presenti condizioni di allarme. Il modo MANUALE sarà usato per l'azzeramento delle stazioni di lavoro, sblocco anomalie, o riposizionamento in condizioni utili per partire con la produzione. - Modo TEST (SBLOCCAPORTE), che consentirà: - di accedere alla zona di lavoro per eseguire la sostituzione degli utensili o le regolazioni necessarie per cambio codice prodotto da lavorare, in quanto le porte di accesso alla zona di lavoro saranno sbloccate e tutte le utenze elettriche saranno in arresto sicuro (in questa condizione il circuito pneumatico non viene scaricato dalla pressione). Non è previsto l'uso del terminale portatile di zona; - (in associazione all'inserimento di credenziali di utente ad alto livello) la programmazione di una ricetta con il terminale portatile della zona di pulitura. Solo per operatori qualificati alla programmazione. Quando il selettore modale è su “SBLOCCA PORTE”, tutte le porte interbloccate di accesso alla zona di lavoro di pulitura saranno sbloccate e una volta inserite le credenziali di utente di alto livello sul terminale, sarà possibile utilizzarlo, stando all'interno della cabina di protezione della zona di puliatura (porte sbloccate) e con la possibilità di osservare la posizione delle utenze. Per la tipologia di lavorazioni svolte dalla zona di pulitura, l’operatore addetto alla programmazione avrà la necessità di operare in prossimità degli organi mobili, in modo da verificare non solo la correttezza della ricetta che deve creare, ma anche la qualità delle operazioni di pulitura svolte, garantendo la precisione delle lavorazioni sul pezzo. Per questo motivo, in modalità di TEST con attivazione costante del dispositivo di abilitazione "uomo morto", l'operatore addetto alla programmazione che possiede le credenziali di utente di alto livello, potrà: - Movimentare una sola stazione di lavoro alla volta, un asse alla volta a velocità ridotta oppure la rotazione della spazzola anche alla massima velocità; - Eseguire il test in continuo. Non è invece possibile comandare la rotazione della tavola rotante della zona di pulitura. Il cambio della modalità di funzionamento durante il ciclo di lavoro automatico comporterà un suo arresto. Lo "SBLOCCO PORTE" comporterà il ripristino manuale e riavviamento del ciclo di lavoro. Si daranno misure di protezione mediante le istruzioni. Il selettore modale, insieme al relativo circuito di comando, realizzerà una funzione di sicurezza. Il dispositivo "uomo morto" di abilitazione presente sul terminale portatile realizzerà, insieme al relativo circuito di comando, una funzione di sicurezza. | R22: Nelle istruzioni dell’impianto si riporterà: - L’obbligo di portare con sé la chiave del selettore modale quando si accede alla zona di lavoro di pulitura. - Quando si accede all’area protetta indossare sempre tutti i dispositivi di protezione individuale previsti. - L’obbligo di consegnare le credenziali di utente di alto livello solo a personale addetto alla programmazione addestrato. - L'avvertenza che solo personale addestrato può utilizzare il terminale portatile per la movimentazione delle parti della zona di pulitura all’interno dell’area protetta. - L'avvertenza che, durante le manovre in test, non ci si deve mai posizionare all’interno dello spazio di azione della stazione di lavoro. Mantenersi sempre a distanza di sicurezza. - L'avvertenza che, durante i TEST, è necessario porsi al di fuori della potenziale linea di proiezione sia del pezzo in lavorazione (qualora dovesse sfuggire dalla presa della pinza porta-pezza), sia del materiale asportato o degli utensili (spazzole). | S22: 3 | T22: 2 | U22: 1 | V22: 1 | W22: =IF(COUNT(T22:V22)=3,SUM(T22:V22),"") -> 4 | X22: =IF(OR(S22="",W22=""),"",INDEX(Metodo!$C$6:$G$9,MATCH(S22,Metodo!$B$6:$B$9,0),MATCH(W22,Metodo!$C$5:$G$5,1))) -> OK | Y22: Norme A: EN ISO 12100 Norme B: EN ISO 13849-1; EN 62061; EN 60204-1 | Norme: ISO/TR 14121-2
